<?xml version="1.0" encoding="utf-8"?>
<!-- This URDF was automatically created by SolidWorks to URDF Exporter! Originally created by Stephen Brawner (brawner@gmail.com) 
     Commit Version: 1.6.0-1-g15f4949  Build Version: 1.6.7594.29634
     For more information, please see http://wiki.ros.org/sw_urdf_exporter -->
<robot name="arm9">

<!--
  <link name="world" /> 
  <joint name="world_to_base_link" type="fixed">
    <parent link="world"/>
    <child link="base_link"/>
    <origin xyz="0 0 0.85" rpy="0 0 0"/>
  </joint>-->

  <!--<link name="base_link">-->
  <!--
  <link name="arm_base_link">
    <inertial>
      <origin
        xyz="-3.30401760475357E-07 -8.1587911850145E-08 -0.171811205539945"
        rpy="0 0 0" />
      <mass
        value="2.87260533420885" />
      <inertia
        ixx="1.00544706217443"
        ixy="-1.56950989393431E-09"
        ixz="1.24228781402058E-07"
        iyy="1.00544450138953"
        iyz="3.13171516678699E-08"
        izz="1.51302717704261" />
    </inertial>
    <visual>
      <origin
        xyz="0 0 0"
        rpy="0 0 0" />
      <geometry>
        <mesh
          filename="package://arm9/meshes/base_link.STL" />
      </geometry>
      <material
        name="">
        <color
          rgba="0.792156862745098 0.819607843137255 0.933333333333333 1" />
      </material>
    </visual>
    <collision>
      <origin
        xyz="0 0 0"
        rpy="0 0 0" />
      <geometry>
        <mesh
          filename="package://arm9/meshes/base_link.STL" />
      </geometry>
    </collision>
  </link>-->
  
  <link name="top-link">
    <inertial>
      <origin
        xyz="0 0 0"
        rpy="0 0 0" />
      <mass
        value="0.0323596733773181" />
      <inertia
        ixx="7.55392831146744E-06"
        ixy="6.50055325428268E-11"
        ixz="2.14614859793023E-12"
        iyy="1.82259507284938E-05"
        iyz="-9.70159399608393E-13"
        izz="1.62361180068E-05" />
    </inertial>
    <visual>
      <origin
        xyz="0 0 0"
        rpy="0 0 0" />
      <geometry>
        <mesh
          filename="package://arm9/meshes/top-link.STL" />
      </geometry>
      <material
        name="">
        <color
          rgba="0.792156862745098 0.819607843137255 0.933333333333333 1" />
      </material>
    </visual>
    <collision>
      <origin
        xyz="0 0 0"
        rpy="0 0 0" />
      <geometry>
        <mesh
          filename="package://arm9/meshes/top-link.STL" />
      </geometry>
    </collision>
  </link>
  
  <link
    name="crossbar">
    <inertial>
      <origin
        xyz="4.9361886397814E-08 2.56190435532488E-09 1.38777878078145E-17"
        rpy="0 0 0" />
      <mass
        value="0.0185865713783782" />
      <inertia
        ixx="4.09739927419315E-06"
        ixy="-5.54410070107033E-13"
        ixz="2.19723759796361E-22"
        iyy="7.42166622150847E-06"
        iyz="8.26818556444033E-12"
        izz="4.09739648427647E-06" />
    </inertial>
    <visual>
      <origin
        xyz="0 0 0"
        rpy="0 0 0" />
      <geometry>
        <mesh
          filename="package://arm9/meshes/crossbar.STL" />
      </geometry>
      <material
        name="">
        <color
          rgba="0.792156862745098 0.819607843137255 0.933333333333333 1" />
      </material>
    </visual>
    <collision>
      <origin
        xyz="0 0 0"
        rpy="0 0 0" />
      <geometry>
        <mesh
          filename="package://arm9/meshes/crossbar.STL" />
      </geometry>
    </collision>
  </link>
  <joint
    name="joint2"
    type="revolute">
    <origin
      xyz="0 0 -0.025"
      rpy="1.5708 0 0" />
    <parent
      link="top-link" />
    <child
      link="crossbar" />
    <axis
      xyz="1 0 0" />
    <limit
      lower="-1.5"
      upper="1.5"
      effort="2"
      velocity="2" />
    <dynamics
      friction="0.01" />
  </joint>
  <link
    name="middle-link">
    <inertial>
      <origin
        xyz="-5.67049394195607E-06 1.16782236728175E-08 -0.327228482133511"
        rpy="0 0 0" />
      <mass
        value="0.475246778728706" />
      <inertia
        ixx="0.0178243730885176"
        ixy="2.97210970662186E-09"
        ixz="7.61997708823829E-07"
        iyy="0.0178456192570225"
        iyz="-1.09658237064635E-09"
        izz="7.79528566357621E-05" />
    </inertial>
    <visual>
      <origin
        xyz="0 0 0"
        rpy="0 0 0" />
      <geometry>
        <mesh
          filename="package://arm9/meshes/middle-link.STL" />
      </geometry>
      <material
        name="">
        <color
          rgba="0.792156862745098 0.819607843137255 0.933333333333333 1" />
      </material>
    </visual>
    <collision>
      <origin
        xyz="0 0 0"
        rpy="0 0 0" />
      <geometry>
        <mesh
          filename="package://arm9/meshes/middle-link.STL" />
      </geometry>
    </collision>
  </link>
  <joint
    name="joint3"
    type="revolute">
    <origin
      xyz="0 0 0"
      rpy="-1.5708 1.5708 0" />
    <parent
      link="crossbar" />
    <child
      link="middle-link" />
    <axis
      xyz="1 0 0" />
    <limit
      lower="-1.5"
      upper="1.5"
      effort="2"
      velocity="2" />
    <dynamics
      friction="0.01" />
  </joint>
  <link
    name="crossbar2">
    <inertial>
      <origin
        xyz="4.93618865643475E-08 2.56190391123567E-09 3.81639164714898E-17"
        rpy="0 0 0" />
      <mass
        value="0.0185865713783782" />
      <inertia
        ixx="4.09739927419315E-06"
        ixy="-5.54410068536451E-13"
        ixz="8.96638089354031E-22"
        iyy="7.42166622150847E-06"
        iyz="8.26818556470318E-12"
        izz="4.09739648427647E-06" />
    </inertial>
    <visual>
      <origin
        xyz="0 0 0"
        rpy="0 0 0" />
      <geometry>
        <mesh
          filename="package://arm9/meshes/crossbar2.STL" />
      </geometry>
      <material
        name="">
        <color
          rgba="0.792156862745098 0.819607843137255 0.933333333333333 1" />
      </material>
    </visual>
    <collision>
      <origin
        xyz="0 0 0"
        rpy="0 0 0" />
      <geometry>
        <mesh
          filename="package://arm9/meshes/crossbar2.STL" />
      </geometry>
    </collision>
  </link>
  <joint
    name="joint4"
    type="revolute">
    <origin
      xyz="0 0 -0.65"
      rpy="-1.5708 0 3.1416" />
    <parent
      link="middle-link" />
    <child
      link="crossbar2" />
    <axis
      xyz="1 0 0" />
    <limit
      lower="-1.5"
      upper="1.5"
      effort="0"
      velocity="0" />
    <dynamics
      friction="0.01" />
  </joint>
  <link
    name="end-effector">
    <inertial>
      <origin
        xyz="3.1484890611333E-08 -5.72836209022931E-10 -0.0356901523983696"
        rpy="0 0 0" />
      <mass
        value="0.0855980769451605" />
      <inertia
        ixx="4.58199537370242E-05"
        ixy="1.60691899374042E-11"
        ixz="-6.16258339494524E-11"
        iyy="5.6392751791086E-05"
        iyz="1.37503787080033E-12"
        izz="4.76465680795506E-05" />
    </inertial>
    <visual>
      <origin
        xyz="0 0 0"
        rpy="0 0 0" />
      <geometry>
        <mesh
          filename="package://arm9/meshes/end-effector.STL" />
      </geometry>
      <material
        name="">
        <color
          rgba="0.792156862745098 0.819607843137255 0.933333333333333 1" />
      </material>
    </visual>
    <collision>
      <origin
        xyz="0 0 0"
        rpy="0 0 0" />
      <geometry>
        <mesh
          filename="package://arm9/meshes/end-effector.STL" />
      </geometry>
    </collision>
  </link>
  <joint
    name="joint5"
    type="revolute">
    <origin
      xyz="0 0 0"
      rpy="1.5708 1.5708 0" />
    <parent
      link="crossbar2" />
    <child
      link="end-effector" />
    <axis
      xyz="1 0 0" />
    <limit
      lower="-1.5"
      upper="1.5"
      effort="0"
      velocity="0" />
    <dynamics
      friction="0.01" />
  </joint>

  <!-- Transmission for control-->
  <transmission name="joint2_tran">
    <type>transmission_interface/SimpleTransmission</type>
    <joint name="joint2">
      <hardwareInterface>hardware_interface/EffortJointInterface</hardwareInterface>
    </joint>
    <actuator name="joint2_actr">
      <hardwareInterface>hardware_interface/EffortJointInterface</hardwareInterface>
      <mechanicalReduction>1</mechanicalReduction>
    </actuator>
  </transmission>

  <transmission name="joint3_tran">
    <type>transmission_interface/SimpleTransmission</type>
    <joint name="joint3">
      <hardwareInterface>hardware_interface/EffortJointInterface</hardwareInterface>
    </joint>
    <actuator name="joint3_actr">
      <hardwareInterface>hardware_interface/EffortJointInterface</hardwareInterface>
      <mechanicalReduction>1</mechanicalReduction>
    </actuator>
  </transmission>

  <gazebo>
    <plugin name="gazebo_ros_control" filename="libgazebo_ros_control.so">
      <robotNamespace>/arm9</robotNamespace>
    </plugin>
  </gazebo>

</robot>